Workbook

Sheet Istruzioni
B2: Domande per il gestionale — Cantina Marramiero
B3: Versione del 25/09/2026. Raccoglie le informazioni che servono per configurare il gestionale: produzione (vigneto, cantina, imbottigliamento, registro), magazzino, personale e amministrazione.
B4: Come si compila
B5: 1. Nel foglio «Domande» filtra la colonna «Chi risponde» per vedere le domande che ti riguardano.
B6: 2. Scrivi nella colonna gialla «Risposta». Se la risposta è un file o un documento, scrivi il nome del file o dove trovarlo.
B7: 3. Compila «Risposto da» e «Data».
B8: 4. Cambia lo «Stato» dal menu a tendina: «Risposta data» quando hai risposto, «Da chiarire» se hai un dubbio (scrivilo nelle «Note»). La riga si colora da sola.
B9: 5. Non cambiare la colonna «ID»: serve per caricare le risposte nel gestionale.
B10: 6. Se non sai rispondere, lascia vuoto e scrivi nelle «Note» chi potrebbe saperlo.
B11: Priorità
B12: Alta: serve nelle prossime settimane (anagrafiche di vigneto e cantina, registro dei trattamenti). Media: serve nei prossimi mesi. Bassa: quando c'è tempo.
B13: Gli altri fogli
... B19: Rimandate il file a Dante. Anche un file compilato a metà va bene: le risposte si caricano un po' alla volta.

Sheet Domande
A1: ID | B1: Area | C1: Domanda | D1: Perché serve | E1: Esempio / possibili risposte | F1: Chi risponde | G1: Priorità | H1: Serve per | I1: Risposta | J1: Risposto da | K1: Data | L1: Stato | M1: Note
A2: AZ-01 | B2: Azienda | C2: Chi sono i referenti di ogni area (enologo, agronomo, responsabile qualità, capo cantina, magazzino, amministrazione)? Nome ed email. | D2: Il software manda a loro approvazioni, avvisi e scadenze. | E2: Enologo: Mario Rossi, m.rossi@… | F2: Direzione | G2: Alta | H2: Portale | L2: Da chiedere
A3: AZ-02 | B3: Azienda | C3: L'enologo è interno o un consulente esterno? Deve poter entrare nel portale? | D3: Assemblaggi, aggiunte e sblocchi dei lotti li approva l'enologo. | E3: Interno / esterno con accesso / esterno senza accesso | F3: Direzione | G3: Alta | H3: Produzione – anagrafiche | I3: Enologo interno; ci sono anche consulenti esterni. | J3: Dante Marramiero | K3: 25/09/2026 | L3: Da chiarire | M3: I consulenti esterni devono entrare nel portale? Per quali aree?
A4: AZ-03 | B4: Azienda | C4: Che dispositivi userete in cantina e in vigneto? | D4: Decide come costruire le schermate e cosa deve funzionare senza rete. | E4: iPad, tablet Android, smartphone aziendali, smartphone personali | F4: Direzione | G4: Alta | H4: Produzione – anagrafiche | I4: Un po' di tutto: iPad, tablet Android, smartphone aziendali e personali. | J4: Dante Marramiero | K4: 25/09/2026 | L4: Risposta data
A5: AZ-04 | B5: Azienda | C5: C'è copertura internet (Wi-Fi o 4G) in cantina, in bottaia e nei vigneti? Dove manca? | D5: Dove manca il segnale le registrazioni si salvano come bozza sul dispositivo e partono dopo. | E5: Cantina sì, bottaia no, vigneto X debole | F5: Cantiniere | G5: Media | H5: Produzione – vigneto | L5: Da chiedere
A6: AZ-05 | B6: Azienda | C6: Come preferite vedere le quantità a schermo: litri o ettolitri? chili o quintali? °Babo o °Brix? | D6: I dati si salvano sempre precisi; cambia solo come si vedono. | E6: hl, kg, °Babo | F6: Enologo | G6: Alta | H6: Produzione – anagrafiche | I6: Le unità si scelgono in Impostazioni. Valori di partenza: ettolitri e quintali. | J6: Dante Marramiero | K6: 25/09/2026 | L6: Da chiarire | M6: Manca la scala degli zuccheri: °Babo o °Brix? (da chiedere all'enologo)
A7: AZ-06 | B7: Azienda | C7: Qualcuno userà il software in inglese? | D7: Testi da preparare anche in inglese. | E7: No / Sì, l'enologo consulente | F7: Direzione | G7: Bassa | H7: Portale | L7: Da chiedere
A8: SIA-01 | B8: Registro SIAN | C8: Chi tiene oggi il registro telematico SIAN: voi, un CAA, un consulente o un altro software? | D8: Il software non deve mai trasmettere al SIAN in parallelo a chi lo fa già. | E8: Consulente Studio X / CAA / software Y / noi dal portale SIAN | F8: Amministrazione | G8: Alta | H8: Produzione – registro SIAN | L8: Da chiedere | M8: 25/09/2026: Dante non lo sa, da chiedere in amministrazione.
A9: SIA-02 | B9: Registro SIAN | C9: Se un software o un servizio trasmette già al SIAN: quale? Deve continuare a farlo lui? | D9: Stabilisce se il nostro software prepara solo i dati da passare o, più avanti, trasmette. | E9: Nome del software o del servizio | F9: Amministrazione | G9: Alta | H9: Produzione – registro SIAN | L9: Da chiedere
A10: SIA-03 | B10: Registro SIAN | C10: Quanti stabilimenti avete con codice ICQRF? Quali sono i codici? | D10: C'è un registro per stabilimento: vasi e operazioni si collegano al loro stabilimento. | E10: 1 stabilimento, codice … | F10: Amministrazione | G10: Alta | H10: Produzione – anagrafiche | L10: Da chiedere | M10: 25/09/2026: Dante non lo sa, da chiedere in amministrazione.
A11: SIA-04 | B11: Registro SIAN | C11: Siete in regime ordinario o in deroga (sotto i 1000 hl l'anno, da uve prevalentemente proprie)? | D11: Cambiano le scadenze: entro il giorno lavorativo dopo / il terzo, oppure 30 giorni. | E11: Ordinario / Deroga 30 giorni | F11: Consulente SIAN/CAA | G11: Alta | H11: Produzione – registro SIAN | L11: Da chiedere | M11: 25/09/2026: Dante non lo sa, da chiedere al consulente.
A12: SIA-05 | B12: Registro SIAN | C12: Siete deposito fiscale (accise)? | D12: Cambiano obblighi e documenti. | E12: Sì / No | F12: Amministrazione | G12: Media | H12: Produzione – registro SIAN | L12: Da chiedere | M12: 25/09/2026: Dante non lo sa, da chiedere in amministrazione.
A13: SIA-06 | B13: Registro SIAN | C13: Quanti ettolitri e quante bottiglie producete in un anno, circa? | D13: Conferma il regime e dimensiona il registro. | E13: 1.200 hl, 150.000 bottiglie | F13: Direzione | G13: Media | H13: Produzione – registro SIAN | L13: Da chiedere
A14: SIA-07 | B14: Registro SIAN | C14: Chi prepara la dichiarazione di vendemmia e produzione (30/11) e quella di giacenza (31/7)? Con quali dati? | D14: Il software può preparare i prospetti già compilati. | E14: Il consulente, dai nostri Excel | F14: Amministrazione | G14: Media | H14: Produzione – registro SIAN | L14: Da chiedere
A15: SIA-08 | B15: Registro SIAN | C15: Potete farvi dare dal consulente l'elenco dei codici operazione SIAN che usate più spesso? | D15: Ogni operazione di cantina va abbinata al suo codice SIAN: non va inventato. | E15: Elenco o file del consulente | F15: Consulente SIAN/CAA | G15: Media | H15: Produzione – registro SIAN | L15: Da chiedere
A16: SIA-09 | B16: Registro SIAN | C16: Vendete o comprate vino sfuso? | D16: Lo sfuso viaggia con documenti MVV: il software fornisce i dati del lotto. | E16: No / Sì, a … | F16: Direzione | G16: Bassa | H16: Produzione – registro SIAN | L16: Da chiedere
A17: SIA-10 | B17: Registro SIAN | C17: Come numerate i documenti giustificativi citati nel registro (DDT, fatture, documenti interni)? | D17: Ogni riga del registro indica il suo documento. | E17: DDT n. 123/2026 | F17: Amministrazione | G17: Bassa | H17: Produzione – registro SIAN | L17: Da chiedere
A18: DEN-01 | B18: Denominazioni e prodotti | C18: Quali denominazioni producete (DOCG, DOC, IGT, varietali, generici) e con quali vini? | D18: Designazione dei lotti, rese massime e regole del disciplinare. | E18: Montepulciano d'Abruzzo DOC: Inferi; Trebbiano d'Abruzzo DOC: Altare | F18: Enologo | G18: Alta | H18: Produzione – anagrafiche | I18: Montepulciano d'Abruzzo DOC, Trebbiano d'Abruzzo DOC, Cerasuolo d'Abruzzo DOC, Abruzzo DOC / IGT e altre. | J18: Dante Marramiero | K18: 25/09/2026 | L18: Nell'onboarding | M18: L'elenco completo, con i vini, si raccoglie nell'onboarding.
A19: DEN-02 | B19: Denominazioni e prodotti | C19: Quali denominazioni richiedono i contrassegni di Stato (fascette)? Chi ve li fornisce? Come registrate serie usate e distrutte? | D19: Etichettatura e quadratura delle fascette. | E19: Nessuna / DOCG X: fascette dal Consorzio | F19: Enologo | G19: Media | H19: Produzione – imbottigliamento | I19: Sì. | J19: Dante Marramiero | K19: 25/09/2026 | L19: Da chiarire | M19: Indicare quali denominazioni, chi fornisce le fascette e come si registrano le serie usate e distrutte.
A20: DEN-03 | B20: Denominazioni e prodotti | C20: Quali menzioni usate (Riserva, Superiore, Vigna…) e su quali vini? | D20: Il software controlla i tempi minimi in legno e di affinamento. | E20: Inferi: Riserva | F20: Enologo | G20: Media | H20: Produzione – affinamento | L20: Da chiedere
A21: DEN-04 | B21: Denominazioni e prodotti | C21: Avete i disciplinari aggiornati delle vostre denominazioni? Potete mandarli? | D21: Rese, vitigni e tempi minimi diventano regole del software. | E21: PDF dei disciplinari | F21: Enologo | G21: Media | H21: Produzione – anagrafiche | L21: Da chiedere
A22: DEN-05 | B22: Denominazioni e prodotti | C22: Elenco completo delle etichette: vino, annata, formato, codice interno (SKU), codice EAN. | D22: Oggi i prodotti nel software non hanno codice né formato. | E22: Inferi 2019, 0,75 L, SKU INF19-075, EAN … | F22: Commerciale | G22: Alta | H22: Magazzino | L22: Nell'onboarding | M22: Elenco delle etichette con il modello dell'onboarding.
A23: DEN-06 | B23: Denominazioni e prodotti | C23: Chi assegna i codici prodotto (SKU)? Con che regola? | D23: I codici collegano imbottigliamento, magazzino e vendite. | E23: Sigla vino + annata + formato | F23: Direzione | G23: Alta | H23: Magazzino | L23: Da chiedere
A24: DEN-07 | B24: Denominazioni e prodotti | C24: Quali formati usate (0,375 / 0,75 / 1,5 / 3 L / altri)? | D24: Imbottigliamenti e materiali per formato. | E24: 0,75 e 1,5 | F24: Enologo | G24: Media | H24: Produzione – imbottigliamento | L24: Da chiedere
A25: DEN-08 | B25: Denominazioni e prodotti | C25: Avete varianti di etichetta per paese, lingua o importatore (retroetichette)? Quali? | D25: L'ordine indica la variante; l'etichettatura scarica i materiali giusti. | E25: Retro USA, retro Giappone per l'importatore X | F25: Commerciale | G25: Media | H25: Produzione – imbottigliamento | L25: Da chiedere
A26: DEN-09 | B26: Denominazioni e prodotti | C26: Quando indicate annata o vitigno in etichetta applicate la regola dell'85%? Ci sono eccezioni? | D26: Il software avvisa quando un assemblaggio fa perdere il diritto a indicarli. | E26: Sì, 85% | F26: Enologo | G26: Media | H26: Produzione – cantina | L26: Da chiedere
A27: VIG-01 | B27: Vigneto | C27: Quanti vigneti e quante parcelle gestite? Come le chiamate oggi (nomi o codici)? | D27: È la base: ogni intervento e ogni conferimento parte da una parcella. | E27: 3 vigneti, 25 parcelle, codici V1-P01… | F27: Agronomo | G27: Alta | H27: Produzione – anagrafiche | L27: Nell'onboarding | M27: Elenco di vigneti e parcelle con il modello dell'onboarding.
A28: VIG-02 | B28: Vigneto | C28: Avete lo schedario viticolo aggiornato e i dati catastali (comune, foglio, particella, subalterno, superficie)? | D28: Superfici vitate, rese per ettaro, dichiarazione di vendemmia. | E28: Sì, dal fascicolo aziendale / dal CAA | F28: Agronomo | G28: Alta | H28: Produzione – anagrafiche | L28: Da chiedere
A29: VIG-03 | B29: Vigneto | C29: Una parcella può stare su più particelle catastali? E una particella può contenere più parcelle? | D29: Decide come collegare parcelle e catasto. | E29: Sì, la parcella X è su 2 particelle | F29: Agronomo | G29: Alta | H29: Produzione – anagrafiche | L29: Da chiedere
A30: VIG-04 | B30: Vigneto | C30: Siete biologici certificati o in conversione, anche solo su una parte dei vigneti? Con quale ente? | D30: Il software blocca i prodotti non ammessi in biologico su quelle parcelle. | E30: Certificati su tutto (ente …) / in conversione sul vigneto X / no | F30: Agronomo | G30: Alta | H30: Produzione – vigneto | I30: In parte: alcuni vigneti sono biologici (certificati o in conversione). | J30: Dante Marramiero | K30: 25/09/2026 | L30: Da chiarire | M30: Indicare quali vigneti, se certificati o in conversione, e l'ente certificatore.
A31: VIG-05 | B31: Vigneto | C31: Avete altre certificazioni (SQNPI, Equalitas, VIVA…)? | D31: Possono chiedere registrazioni in più. | E31: No / Equalitas | F31: Direzione | G31: Bassa | H31: Produzione – vigneto | L31: Da chiedere
A32: VIG-06 | B32: Vigneto | C32: Come registrate oggi i trattamenti (quaderno di carta, Excel, software, CAA)? Chi li scrive? | D32: Dal 1/1/2027 il registro dei trattamenti sarà solo elettronico; quelli del 2026 vanno convertiti entro il 31/12/2026. | E32: Quaderno di carta compilato dal trattorista | F32: Agronomo | G32: Alta | H32: Produzione – vigneto | L32: Da chiedere
A33: VIG-07 | B33: Vigneto | C33: Chi esegue i trattamenti? Hanno il patentino fitosanitario valido? Fino a quando? | D33: Il software accetta come esecutore solo chi ha il patentino valido alla data. | E33: 2 trattoristi, patentino fino al 2028 | F33: Agronomo | G33: Alta | H33: Produzione – vigneto | L33: Da chiedere
A34: VIG-08 | B34: Vigneto | C34: Elenco delle irroratrici e delle attrezzature, con la data dell'ultimo controllo funzionale. | D34: Un trattamento con un'attrezzatura non controllata viene segnalato. | E34: Atomizzatore X, controllo marzo 2025 | F34: Agronomo | G34: Alta | H34: Produzione – vigneto | L34: Nell'onboarding | M34: Elenco delle attrezzature con il modello dell'onboarding.
A35: VIG-09 | B35: Vigneto | C35: Quali fitofarmaci usate? (nome, n. di registrazione, dose massima, carenza, rientro, n. massimo di applicazioni, ammesso in bio) | D35: Controlli su dosi, giorni di carenza e tempi di rientro. | E35: Modello «Fitofarmaci» dell’onboarding | F35: Agronomo | G35: Alta | H35: Produzione – vigneto | L35: Nell'onboarding | M35: Elenco dei fitofarmaci con il modello dell'onboarding.
A36: VIG-10 | B36: Vigneto | C36: I fitofarmaci li gestite a magazzino (carichi e scarichi)? | D36: Se sì, ogni trattamento scarica il prodotto dal magazzino. | E36: Sì / No | F36: Agronomo | G36: Media | H36: Produzione – vigneto | L36: Da chiedere
A37: VIG-11 | B37: Vigneto | C37: Il numero massimo di applicazioni di un prodotto lo contate per anno solare? | D37: La campagna (1/8–31/7) spezza in due la stagione dei trattamenti: proponiamo di contare per anno solare. | E37: Sì, per anno solare | F37: Agronomo | G37: Alta | H37: Produzione – vigneto | L37: Chiesta | M37: 25/09/2026: Dante lo chiede all'agronomo (è la decisione DP13).
A38: VIG-12 | B38: Vigneto | C38: Quali analisi di maturazione fate (zuccheri, acidità, pH, malico, peso acini, APA, maturità fenolica, sanità)? Ogni quanto e chi le fa? | D38: Curve di maturazione per parcella e previsione della vendemmia. | E38: °Babo, acidità e pH ogni 5 giorni da fine agosto | F38: Enologo | G38: Media | H38: Produzione – vigneto | L38: Da chiedere
A39: VIG-13 | B39: Vigneto | C39: Quali valori obiettivo usate per decidere quando vendemmiare (base spumante, bianco, rosso)? | D39: Previsione della data di vendemmia. | E39: Base spumante: 17-18 °Brix, acidità > 8 g/l | F39: Enologo | G39: Media | H39: Produzione – vigneto | L39: Da chiedere
A40: VIG-14 | B40: Vigneto | C40: Oltre ai trattamenti, quali interventi volete registrare (potature, lavorazioni, concimazioni, irrigazioni, sfalci, diradamenti…)? | D40: Storico per parcella e costi di vigneto. | E40: Tutti / solo concimazioni e potature | F40: Agronomo | G40: Media | H40: Produzione – vigneto | L40: Da chiedere
...

Sheet Dati per l'onboarding
A1: ID | B1: Dati | C1: Colonne minime | D1: Chi lo prepara | E1: Serve per | F1: Priorità | G1: Stato | H1: Note
A2: FOG-01 | B2: Parcelle | C2: codice, nome, vigneto, vitigno, clone, portinnesto, anno d'impianto, sesto (cm × cm), n. ceppi, forma di allevamento, esposizione, altitudine, superficie vitata m², DO idonee, biologico | D2: Agronomo | E2: Produzione – anagrafiche | F2: Alta | G2: Da preparare
A3: FOG-02 | B3: Particelle catastali | C3: comune, foglio, particella, subalterno, superficie catastale m², parcelle che contiene con la superficie vitata, codice unità vitata dello schedario | D3: Agronomo | E3: Produzione – anagrafiche | F3: Alta | G3: Da preparare
A4: FOG-03 | B4: Vasi | C4: codice, tipo (inox, cemento, tino, botte, anfora, autoclave…), materiale, capacità in litri, luogo, termocondizionato sì/no, spazio confinato sì/no | D4: Cantiniere | E4: Produzione – anagrafiche | F4: Alta | G4: Da preparare
A5: FOG-04 | B5: Barrique e legni | C5: codice, tonnelleria, origine del rovere, foresta, grana, tostatura, capacità in litri, data d'acquisto, costo, passaggi già fatti | D5: Cantiniere | E5: Produzione – anagrafiche | F5: Alta | G5: Da preparare
A6: FOG-05 | B6: Vini in cantina oggi | C6: vaso, codice lotto, vino, annata, volume in litri, vitigni con %, denominazione, stato (mosto, vino, base spumante, sui lieviti…) | D6: Enologo | E6: Produzione – vendemmia e lotti | F6: Alta | G6: Da preparare
A7: FOG-06 | B7: Fitofarmaci | C7: nome commerciale, n. di registrazione, sostanza attiva, dose massima per ettaro, unità, giorni di carenza, ore di rientro, n. massimo di applicazioni l'anno, ammesso in biologico | D7: Agronomo | E7: Produzione – vigneto | F7: Alta | G7: Da preparare
A8: FOG-07 | B8: Trattamenti 2026 | C8: il registro dei trattamenti di quest'anno così com'è (foto del quaderno, Excel o export) | D8: Agronomo | E8: Produzione – vigneto | F8: Alta | G8: Da preparare
A9: FOG-08 | B9: Attrezzature | C9: nome, tipo, targa o matricola, data dell'ultimo controllo funzionale (irroratrici) | D9: Agronomo | E9: Produzione – vigneto | F9: Alta | G9: Da preparare
A10: FOG-09 | B10: Prodotti enologici | C10: nome, tipo (lievito, batteri, enzima, solfiti, bentonite…), fornitore, unità, lotto e scadenza tracciati sì/no | D10: Enologo | E10: Produzione – cantina | F10: Media | G10: Da preparare
A11: FOG-10 | B11: Materiali secchi | C11: codice, nome (bottiglie, tappi, capsule, gabbiette, etichette, cartoni…), unità, fornitore, scorta minima, giacenza di oggi | D11: Magazzino | E11: Magazzino | F11: Alta | G11: Da preparare
A12: FOG-11 | B12: Etichette e prodotti finiti | C12: vino, annata, formato, SKU, EAN, varianti di etichetta | D12: Commerciale | E12: Magazzino | F12: Alta | G12: Da preparare
A13: FOG-12 | B13: Distinte materiali | C13: per ogni vino e formato: materiali e quantità per bottiglia, separati tra imbottigliamento, etichettatura e confezionamento | D13: Magazzino | E13: Produzione – imbottigliamento | F13: Media | G13: Da preparare
... A17: FOG-16 | B17: Analisi di maturazione degli anni passati | C17: parcella, data, zuccheri, acidità, pH e gli altri parametri che misurate | D17: Enologo | E17: Produzione – vigneto | F17: Bassa | G17: Da preparare

Sheet Soglie da validare
A1: ID | B1: Soglia | C1: Valore proposto | D1: Regola | E1: Fonte da verificare | F1: Chi valida | G1: Valore confermato | H1: Validato da | I1: Data | J1: Stato | K1: Note
A2: SOG-01 | B2: Finestra in cui sono ammesse le fermentazioni | C2: 15/7 → 31/12 (salvo deroghe) | D2: PRD-H05 | E2: Normativa nazionale; deroghe da disciplinare | F2: Consulente SIAN/CAA | J2: Da validare
A3: SOG-02 | B3: Acidificazione registrabile senza dichiarazione preventiva | C3: 4 g/l in acido tartarico | D3: PRD-C10 | E3: Normativa sulle pratiche enologiche | F3: Enologo | J3: Da validare
A4: SOG-03 | B4: Quota minima per indicare annata o vitigno | C4: 85% | D4: PRD-C06 | E4: Normativa sull'etichettatura | F4: Enologo | J4: Da validare
A5: SOG-04 | B5: Arresto di fermentazione | C5: Densità ferma per 48 ore (calo minimo da definire) | D5: PRD-C12 | E5: Pratica di cantina | F5: Enologo | J5: Da validare
A6: SOG-05 | B6: Trattamento registrato in ritardo | C6: Oltre 30 giorni dall'esecuzione | D6: PRD-V08 | E6: Normativa sul registro dei trattamenti | F6: Agronomo | J6: Da validare
A7: SOG-06 | B7: Tempo minimo sui lieviti (metodo classico) | C7: 9 mesi, per tipologia e menzione | D7: PRD-M02 | E7: Disciplinari e normativa UE | F7: Enologo | J7: Da validare
A8: SOG-07 | B8: Tolleranza di un travaso senza calo dichiarato | C8: 0,5% del volume | D8: PRD-C04 | E8: Pratica di cantina | F8: Enologo | J8: Da validare
A9: SOG-08 | B9: SO2 totale: soglia di attenzione e limite, per categoria | C9: Da tabella (fermi, spumanti, biologico, zuccheri residui) | D9: PRD-C14 | E9: Normativa UE sulle pratiche enologiche | F9: Enologo | J9: Da validare
A10: SOG-09 | B10: Acidità volatile: soglia di attenzione e limite | C10: Da tabella per bianchi, rosati e rossi | D10: PRD-C14 | E10: Normativa UE sulle pratiche enologiche | F10: Enologo | J10: Da validare
A11: SOG-10 | B11: Categorie di dosaggio degli spumanti | C11: Tabella UE (pas dosé … dolce) con tolleranza | D11: PRD-M03 | E11: Normativa UE sull'etichettatura degli spumanti | F11: Enologo | J11: Da validare
A12: SOG-11 | B12: Pressione minima per categoria di spumante | C12: Da tabella | D12: PRD-M05 | E12: Normativa UE | F12: Enologo | J12: Da validare
A13: SOG-12 | B13: Resa massima di uva per ettaro | C13: Dal disciplinare di ogni DO; vini generici 30 t/ha (40 dove previsto) | D13: PRD-H03 | E13: Disciplinari, normativa nazionale | F13: Agronomo | J13: Da validare
... A21: SOG-20 | B21: Avviso prima della scadenza SIAN | C21: 1 giorno lavorativo prima | D21: PRD-S02 | E21: — | F21: Amministrazione | J21: Da validare

Sheet Riepilogo
A1: Per area
A2: Area | B2: Domande | C2: Con risposta | D2: Da chiarire | E2: Nell'onboarding | F2: Mancanti | G2: % fatto
A3: Azienda | B3: =COUNTIF(Domande!$B$2:$B$104,A3) | C3: =COUNTIFS(Domande!$B$2:$B$104,A3,Domande!$L$2:$L$104,"Risposta data") | D3: =COUNTIFS(Domande!$B$2:$B$104,A3,Domande!$L$2:$L$104,"Da chiarire") | E3: =COUNTIFS(Domande!$B$2:$B$104,A3,Domande!$L$2:$L$104,"Nell'onboarding") | F3: =B3-C3-E3 | G3: =IF(B3-E3=0,0,C3/(B3-E3))
A4: Registro SIAN | B4: =COUNTIF(Domande!$B$2:$B$104,A4) | C4: =COUNTIFS(Domande!$B$2:$B$104,A4,Domande!$L$2:$L$104,"Risposta data") | D4: =COUNTIFS(Domande!$B$2:$B$104,A4,Domande!$L$2:$L$104,"Da chiarire") | E4: =COUNTIFS(Domande!$B$2:$B$104,A4,Domande!$L$2:$L$104,"Nell'onboarding") | F4: =B4-C4-E4 | G4: =IF(B4-E4=0,0,C4/(B4-E4))
A5: Denominazioni e prodotti | B5: =COUNTIF(Domande!$B$2:$B$104,A5) | C5: =COUNTIFS(Domande!$B$2:$B$104,A5,Domande!$L$2:$L$104,"Risposta data") | D5: =COUNTIFS(Domande!$B$2:$B$104,A5,Domande!$L$2:$L$104,"Da chiarire") | E5: =COUNTIFS(Domande!$B$2:$B$104,A5,Domande!$L$2:$L$104,"Nell'onboarding") | F5: =B5-C5-E5 | G5: =IF(B5-E5=0,0,C5/(B5-E5))
A6: Vigneto | B6: =COUNTIF(Domande!$B$2:$B$104,A6) | C6: =COUNTIFS(Domande!$B$2:$B$104,A6,Domande!$L$2:$L$104,"Risposta data") | D6: =COUNTIFS(Domande!$B$2:$B$104,A6,Domande!$L$2:$L$104,"Da chiarire") | E6: =COUNTIFS(Domande!$B$2:$B$104,A6,Domande!$L$2:$L$104,"Nell'onboarding") | F6: =B6-C6-E6 | G6: =IF(B6-E6=0,0,C6/(B6-E6))
A7: Vendemmia | B7: =COUNTIF(Domande!$B$2:$B$104,A7) | C7: =COUNTIFS(Domande!$B$2:$B$104,A7,Domande!$L$2:$L$104,"Risposta data") | D7: =COUNTIFS(Domande!$B$2:$B$104,A7,Domande!$L$2:$L$104,"Da chiarire") | E7: =COUNTIFS(Domande!$B$2:$B$104,A7,Domande!$L$2:$L$104,"Nell'onboarding") | F7: =B7-C7-E7 | G7: =IF(B7-E7=0,0,C7/(B7-E7))
A8: Cantina | B8: =COUNTIF(Domande!$B$2:$B$104,A8) | C8: =COUNTIFS(Domande!$B$2:$B$104,A8,Domande!$L$2:$L$104,"Risposta data") | D8: =COUNTIFS(Domande!$B$2:$B$104,A8,Domande!$L$2:$L$104,"Da chiarire") | E8: =COUNTIFS(Domande!$B$2:$B$104,A8,Domande!$L$2:$L$104,"Nell'onboarding") | F8: =B8-C8-E8 | G8: =IF(B8-E8=0,0,C8/(B8-E8))
A9: Metodo classico | B9: =COUNTIF(Domande!$B$2:$B$104,A9) | C9: =COUNTIFS(Domande!$B$2:$B$104,A9,Domande!$L$2:$L$104,"Risposta data") | D9: =COUNTIFS(Domande!$B$2:$B$104,A9,Domande!$L$2:$L$104,"Da chiarire") | E9: =COUNTIFS(Domande!$B$2:$B$104,A9,Domande!$L$2:$L$104,"Nell'onboarding") | F9: =B9-C9-E9 | G9: =IF(B9-E9=0,0,C9/(B9-E9))
A10: Imbottigliamento | B10: =COUNTIF(Domande!$B$2:$B$104,A10) | C10: =COUNTIFS(Domande!$B$2:$B$104,A10,Domande!$L$2:$L$104,"Risposta data") | D10: =COUNTIFS(Domande!$B$2:$B$104,A10,Domande!$L$2:$L$104,"Da chiarire") | E10: =COUNTIFS(Domande!$B$2:$B$104,A10,Domande!$L$2:$L$104,"Nell'onboarding") | F10: =B10-C10-E10 | G10: =IF(B10-E10=0,0,C10/(B10-E10))
A11: Magazzino | B11: =COUNTIF(Domande!$B$2:$B$104,A11) | C11: =COUNTIFS(Domande!$B$2:$B$104,A11,Domande!$L$2:$L$104,"Risposta data") | D11: =COUNTIFS(Domande!$B$2:$B$104,A11,Domande!$L$2:$L$104,"Da chiarire") | E11: =COUNTIFS(Domande!$B$2:$B$104,A11,Domande!$L$2:$L$104,"Nell'onboarding") | F11: =B11-C11-E11 | G11: =IF(B11-E11=0,0,C11/(B11-E11))
A12: Commerciale | B12: =COUNTIF(Domande!$B$2:$B$104,A12) | C12: =COUNTIFS(Domande!$B$2:$B$104,A12,Domande!$L$2:$L$104,"Risposta data") | D12: =COUNTIFS(Domande!$B$2:$B$104,A12,Domande!$L$2:$L$104,"Da chiarire") | E12: =COUNTIFS(Domande!$B$2:$B$104,A12,Domande!$L$2:$L$104,"Nell'onboarding") | F12: =B12-C12-E12 | G12: =IF(B12-E12=0,0,C12/(B12-E12))
A13: Personale e sicurezza | B13: =COUNTIF(Domande!$B$2:$B$104,A13) | C13: =COUNTIFS(Domande!$B$2:$B$104,A13,Domande!$L$2:$L$104,"Risposta data") | D13: =COUNTIFS(Domande!$B$2:$B$104,A13,Domande!$L$2:$L$104,"Da chiarire") | E13: =COUNTIFS(Domande!$B$2:$B$104,A13,Domande!$L$2:$L$104,"Nell'onboarding") | F13: =B13-C13-E13 | G13: =IF(B13-E13=0,0,C13/(B13-E13))
A14: Amministrazione e costi | B14: =COUNTIF(Domande!$B$2:$B$104,A14) | C14: =COUNTIFS(Domande!$B$2:$B$104,A14,Domande!$L$2:$L$104,"Risposta data") | D14: =COUNTIFS(Domande!$B$2:$B$104,A14,Domande!$L$2:$L$104,"Da chiarire") | E14: =COUNTIFS(Domande!$B$2:$B$104,A14,Domande!$L$2:$L$104,"Nell'onboarding") | F14: =B14-C14-E14 | G14: =IF(B14-E14=0,0,C14/(B14-E14))
A15: Sistemi e accessi | B15: =COUNTIF(Domande!$B$2:$B$104,A15) | C15: =COUNTIFS(Domande!$B$2:$B$104,A15,Domande!$L$2:$L$104,"Risposta data") | D15: =COUNTIFS(Domande!$B$2:$B$104,A15,Domande!$L$2:$L$104,"Da chiarire") | E15: =COUNTIFS(Domande!$B$2:$B$104,A15,Domande!$L$2:$L$104,"Nell'onboarding") | F15: =B15-C15-E15 | G15: =IF(B15-E15=0,0,C15/(B15-E15))
A16: Totale | B16: =SUM(B3:B15) | C16: =SUM(C3:C15) | D16: =SUM(D3:D15) | E16: =SUM(E3:E15) | F16: =SUM(F3:F15) | G16: =IF(B16-E16=0,0,C16/(B16-E16))
A18: Per persona
A19: Chi risponde | B19: Domande | C19: Con risposta | D19: Da chiarire | E19: Nell'onboarding | F19: Mancanti | G19: % fatto
A20: Agronomo | B20: =COUNTIF(Domande!$F$2:$F$104,A20) | C20: =COUNTIFS(Domande!$F$2:$F$104,A20,Domande!$L$2:$L$104,"Risposta data") | D20: =COUNTIFS(Domande!$F$2:$F$104,A20,Domande!$L$2:$L$104,"Da chiarire") | E20: =COUNTIFS(Domande!$F$2:$F$104,A20,Domande!$L$2:$L$104,"Nell'onboarding") | F20: =B20-C20-E20 | G20: =IF(B20-E20=0,0,C20/(B20-E20))
A21: Amministrazione | B21: =COUNTIF(Domande!$F$2:$F$104,A21) | C21: =COUNTIFS(Domande!$F$2:$F$104,A21,Domande!$L$2:$L$104,"Risposta data") | D21: =COUNTIFS(Domande!$F$2:$F$104,A21,Domande!$L$2:$L$104,"Da chiarire") | E21: =COUNTIFS(Domande!$F$2:$F$104,A21,Domande!$L$2:$L$104,"Nell'onboarding") | F21: =B21-C21-E21 | G21: =IF(B21-E21=0,0,C21/(B21-E21))
A22: Cantiniere | B22: =COUNTIF(Domande!$F$2:$F$104,A22) | C22: =COUNTIFS(Domande!$F$2:$F$104,A22,Domande!$L$2:$L$104,"Risposta data") | D22: =COUNTIFS(Domande!$F$2:$F$104,A22,Domande!$L$2:$L$104,"Da chiarire") | E22: =COUNTIFS(Domande!$F$2:$F$104,A22,Domande!$L$2:$L$104,"Nell'onboarding") | F22: =B22-C22-E22 | G22: =IF(B22-E22=0,0,C22/(B22-E22))
A23: Commerciale | B23: =COUNTIF(Domande!$F$2:$F$104,A23) | C23: =COUNTIFS(Domande!$F$2:$F$104,A23,Domande!$L$2:$L$104,"Risposta data") | D23: =COUNTIFS(Domande!$F$2:$F$104,A23,Domande!$L$2:$L$104,"Da chiarire") | E23: =COUNTIFS(Domande!$F$2:$F$104,A23,Domande!$L$2:$L$104,"Nell'onboarding") | F23: =B23-C23-E23 | G23: =IF(B23-E23=0,0,C23/(B23-E23))
A24: Commercialista | B24: =COUNTIF(Domande!$F$2:$F$104,A24) | C24: =COUNTIFS(Domande!$F$2:$F$104,A24,Domande!$L$2:$L$104,"Risposta data") | D24: =COUNTIFS(Domande!$F$2:$F$104,A24,Domande!$L$2:$L$104,"Da chiarire") | E24: =COUNTIFS(Domande!$F$2:$F$104,A24,Domande!$L$2:$L$104,"Nell'onboarding") | F24: =B24-C24-E24 | G24: =IF(B24-E24=0,0,C24/(B24-E24))
A25: Consulente del lavoro | B25: =COUNTIF(Domande!$F$2:$F$104,A25) | C25: =COUNTIFS(Domande!$F$2:$F$104,A25,Domande!$L$2:$L$104,"Risposta data") | D25: =COUNTIFS(Domande!$F$2:$F$104,A25,Domande!$L$2:$L$104,"Da chiarire") | E25: =COUNTIFS(Domande!$F$2:$F$104,A25,Domande!$L$2:$L$104,"Nell'onboarding") | F25: =B25-C25-E25 | G25: =IF(B25-E25=0,0,C25/(B25-E25))
A26: Consulente SIAN/CAA | B26: =COUNTIF(Domande!$F$2:$F$104,A26) | C26: =COUNTIFS(Domande!$F$2:$F$104,A26,Domande!$L$2:$L$104,"Risposta data") | D26: =COUNTIFS(Domande!$F$2:$F$104,A26,Domande!$L$2:$L$104,"Da chiarire") | E26: =COUNTIFS(Domande!$F$2:$F$104,A26,Domande!$L$2:$L$104,"Nell'onboarding") | F26: =B26-C26-E26 | G26: =IF(B26-E26=0,0,C26/(B26-E26))
A27: Dante | B27: =COUNTIF(Domande!$F$2:$F$104,A27) | C27: =COUNTIFS(Domande!$F$2:$F$104,A27,Domande!$L$2:$L$104,"Risposta data") | D27: =COUNTIFS(Domande!$F$2:$F$104,A27,Domande!$L$2:$L$104,"Da chiarire") | E27: =COUNTIFS(Domande!$F$2:$F$104,A27,Domande!$L$2:$L$104,"Nell'onboarding") | F27: =B27-C27-E27 | G27: =IF(B27-E27=0,0,C27/(B27-E27))
A28: Direzione | B28: =COUNTIF(Domande!$F$2:$F$104,A28) | C28: =COUNTIFS(Domande!$F$2:$F$104,A28,Domande!$L$2:$L$104,"Risposta data") | D28: =COUNTIFS(Domande!$F$2:$F$104,A28,Domande!$L$2:$L$104,"Da chiarire") | E28: =COUNTIFS(Domande!$F$2:$F$104,A28,Domande!$L$2:$L$104,"Nell'onboarding") | F28: =B28-C28-E28 | G28: =IF(B28-E28=0,0,C28/(B28-E28))
A29: Enologo | B29: =COUNTIF(Domande!$F$2:$F$104,A29) | C29: =COUNTIFS(Domande!$F$2:$F$104,A29,Domande!$L$2:$L$104,"Risposta data") | D29: =COUNTIFS(Domande!$F$2:$F$104,A29,Domande!$L$2:$L$104,"Da chiarire") | E29: =COUNTIFS(Domande!$F$2:$F$104,A29,Domande!$L$2:$L$104,"Nell'onboarding") | F29: =B29-C29-E29 | G29: =IF(B29-E29=0,0,C29/(B29-E29))
A30: Magazzino | B30: =COUNTIF(Domande!$F$2:$F$104,A30) | C30: =COUNTIFS(Domande!$F$2:$F$104,A30,Domande!$L$2:$L$104,"Risposta data") | D30: =COUNTIFS(Domande!$F$2:$F$104,A30,Domande!$L$2:$L$104,"Da chiarire") | E30: =COUNTIFS(Domande!$F$2:$F$104,A30,Domande!$L$2:$L$104,"Nell'onboarding") | F30: =B30-C30-E30 | G30: =IF(B30-E30=0,0,C30/(B30-E30))
A31: Medico competente | B31: =COUNTIF(Domande!$F$2:$F$104,A31) | C31: =COUNTIFS(Domande!$F$2:$F$104,A31,Domande!$L$2:$L$104,"Risposta data") | D31: =COUNTIFS(Domande!$F$2:$F$104,A31,Domande!$L$2:$L$104,"Da chiarire") | E31: =COUNTIFS(Domande!$F$2:$F$104,A31,Domande!$L$2:$L$104,"Nell'onboarding") | F31: =B31-C31-E31 | G31: =IF(B31-E31=0,0,C31/(B31-E31))
... A33: RSPP | B33: =COUNTIF(Domande!$F$2:$F$104,A33) | C33: =COUNTIFS(Domande!$F$2:$F$104,A33,Domande!$L$2:$L$104,"Risposta data") | D33: =COUNTIFS(Domande!$F$2:$F$104,A33,Domande!$L$2:$L$104,"Da chiarire") | E33: =COUNTIFS(Domande!$F$2:$F$104,A33,Domande!$L$2:$L$104,"Nell'onboarding") | F33: =B33-C33-E33 | G33: =IF(B33-E33=0,0,C33/(B33-E33))
A34: Totale | B34: =SUM(B20:B33) | C34: =SUM(C20:C33) | D34: =SUM(D20:D33) | E34: =SUM(E20:E33) | F34: =SUM(F20:F33) | G34: =IF(B34-E34=0,0,C34/(B34-E34))
A36: Dati per l'onboarding pronti | B36: =COUNTIF('Dati per l''onboarding'!$G$2:$G$17,"Pronto")&" su 16"
A37: Soglie validate | B37: =COUNTIF('Soglie da validare'!$J$2:$J$21,"Validata")&" su 20"

Sheet Decisioni software
A1: ID | B1: Tema | C1: Proposta | D1: Decisione | E1: Data | F1: Note
A2: DP1 | B2: Database | C2: Restare su SQLite (come deciso il 24/09), valori analitici come interi × 10.000 | D2: Approvata | E2: 25/09/2026
A3: DP2 | B3: Eventi | C3: Contratto v1 con Finance (docs/produzione/eventi.md); versione e autore su ogni evento | D3: Approvata | E3: 25/09/2026
A4: DP3 | B4: Oggetti di costo | C4: Nuovi tipi parcella, ordine di lavoro, imbottigliamento; lotto collegato al lotto di vino (si ricostruisce la tabella) | D4: Approvata | E4: 25/09/2026
A5: DP4 | B5: Permessi | C5: Capacità per ruolo dentro Produzione: enologo, cantiniere, capo squadra, agronomo, responsabile qualità, sola lettura | D5: Approvata | E5: 25/09/2026
A6: DP5 | B6: Magazzino | C6: Lotti e scadenze delle materie prime, semilavorati, giacenza per variante e lotto; colonne aggiunte alla 0014 prima di pubblicarla | D6: Approvata | E6: 25/09/2026
A7: DP6 | B7: Fuso orario | C7: Ora italiana per Produzione; correzione a parte per i moduli esistenti | D7: Approvata | E7: 25/09/2026
A8: DP7 | B8: Stato di produzione delle righe | C8: Per ora manuale; in Fase 6 automatico solo con il via; «bottiglie spedite» dagli ordini evasi | D8: Approvata | E8: 25/09/2026
A9: DP8 | B9: Varianti di etichetta | C9: Catalogo delle varianti; la riga d'ordine resta testo e si abbina | D9: Approvata | E9: 25/09/2026
A10: DP9 | B10: Schermate | C10: Gestione nel portale + pagina di campo per tablet e smartphone; QR letti con la fotocamera; stampe HTML; bozze offline in vigneto | D10: Approvata | E10: 25/09/2026 | F10: Deve funzionare su tutti i dispositivi: iPad, tablet Android, smartphone aziendali e personali (AZ-03).
A11: DP10 | B11: Testi | C11: Dizionario italiano centralizzato per Produzione, pronto per l'inglese | D11: Approvata | E11: 25/09/2026
A12: DP11 | B12: Codici dei lotti | C12: Seguire la numerazione attuale (vedi CAN-04, IMB-02); proposta 26-PEC-03 e L2626801 | D12: Approvata | E12: 25/09/2026 | F12: La numerazione attuale è da raccogliere (CAN-04, IMB-02).
A13: DP12 | B13: Configurazione normativa | C13: Tabella prd_config con valori «da validare» (foglio Soglie da validare) | D13: Approvata | E13: 25/09/2026
A14: DP13 | B14: Annata agraria | C14: Per il vigneto: anno di vendemmia e anno solare; la campagna 1/8–31/7 per cantina e registro | D14: Aperta: Dante la chiede all'agronomo | E14: 25/09/2026 | F14: Domanda VIG-11.
A15: DP14 | B15: Parcelle e catasto | C15: Elenco delle particelle con superficie e collegamento parcella ↔ particella | D15: Approvata | E15: 25/09/2026
A16: DP15 | B16: Ordine delle fasi | C16: Nucleo del motore delle operazioni già nella Fase 3 | D16: Approvata | E16: 25/09/2026
A17: DP16 | B17: Apertura della cantina | C17: I vini oggi in cantina come punto di partenza, invece di ricostruire la vendemmia 2026 | D17: Rimandata all'onboarding | E17: 25/09/2026 | F17: Si decide con la procedura di onboarding (DP18).
A18: DP17 | B18: Unità di misura | C18: Unità a schermo personalizzabili in Impostazioni (volumi, pesi, zuccheri); si salva sempre in ml e g | D18: Richiesta di Dante | E18: 25/09/2026 | F18: Partenza: ettolitri e quintali; scala degli zuccheri da definire (AZ-05).
A19: DP18 | B19: Onboarding | C19: Procedura dedicata con modelli Excel standard che la cantina compila, separata dalle Impostazioni; da progettare più avanti | D19: Richiesta di Dante | E19: 25/09/2026 | F19: Da progettare più avanti, separata dalle Impostazioni.
